Workbook

Sheet net_carbon_price
A1: STRUCTURE | B1: STRUCTURE_ID | C1: STRUCTURE_NAME | D1: ACTION | E1: REF_AREA | F1: Reference area | G1: SECTOR | H1: Economic sector | I1: EMISSIONS_SOURCE | J1: Emissions source | K1: MEASURE | L1: Measure | M1: PRICE_LEVEL | N1: Carbon price level | O1: UNIT_MEASURE | P1: Unit of measure | Q1: STATISTICAL_OPERATION | R1: Statistical operation | S1: PRICE_BASE | T1: Price base | U1: FREQ | V1: Frequency of observation | W1: TIME_PERIOD | X1: Time period | Y1: OBS_VALUE | Z1: Observation value | AA1: CURRENCY | AB1: Currency | AC1: BASE_PER | AD1: Base period | AE1: OBS_STATUS | AF1: Observation status | AG1: UNIT_MULT | AH1: Unit multiplier | AI1: DECIMALS | AJ1: Decimals
A2: DATAFLOW | B2: OECD.CTP.TPS:DSD_NECR@DF_NECRS(1.1) | C2: Net effective carbon rates | D2: I | E2: AUS | F2: Australia | G2: _T | H2: Total | I2: _T | J2: All sources | K2: NETECR | L2: Net effective carbon rate | M2: _Z | N2: Not applicable | O2: XDC_TCO2E | P2: National currency per tonne of CO2-equivalent | Q2: MEANW | R2: Weighted mean | S2: Q | T2: Constant prices | U2: A | V2: Annual | W2: 2023 | Y2: 33.174026 | AA2: AUD | AB2: Australian dollar | AC2: 2023 | AE2: A | AF2: Normal value | AG2: 0 | AH2: Units | AI2: 2 | AJ2: Two
A3: DATAFLOW | B3: OECD.CTP.TPS:DSD_NECR@DF_NECRS(1.1) | C3: Net effective carbon rates | D3: I | E3: CAN | F3: Canada | G3: _T | H3: Total | I3: _T | J3: All sources | K3: NETECR | L3: Net effective carbon rate | M3: _Z | N3: Not applicable | O3: XDC_TCO2E | P3: National currency per tonne of CO2-equivalent | Q3: MEANW | R3: Weighted mean | S3: Q | T3: Constant prices | U3: A | V3: Annual | W3: 2023 | Y3: 61.561615 | AA3: CAD | AB3: Canadian dollar | AC3: 2023 | AE3: A | AF3: Normal value | AG3: 0 | AH3: Units | AI3: 2 | AJ3: Two
A4: DATAFLOW | B4: OECD.CTP.TPS:DSD_NECR@DF_NECRS(1.1) | C4: Net effective carbon rates | D4: I | E4: CHL | F4: Chile | G4: _T | H4: Total | I4: _T | J4: All sources | K4: NETECR | L4: Net effective carbon rate | M4: _Z | N4: Not applicable | O4: XDC_TCO2E | P4: National currency per tonne of CO2-equivalent | Q4: MEANW | R4: Weighted mean | S4: Q | T4: Constant prices | U4: A | V4: Annual | W4: 2023 | Y4: 33398.207 | AA4: CLP | AB4: Chilean peso | AC4: 2023 | AE4: A | AF4: Normal value | AG4: 0 | AH4: Units | AI4: 2 | AJ4: Two
A5: DATAFLOW | B5: OECD.CTP.TPS:DSD_NECR@DF_NECRS(1.1) | C5: Net effective carbon rates | D5: I | E5: CRI | F5: Costa Rica | G5: _T | H5: Total | I5: _T | J5: All sources | K5: NETECR | L5: Net effective carbon rate | M5: _Z | N5: Not applicable | O5: XDC_TCO2E | P5: National currency per tonne of CO2-equivalent | Q5: MEANW | R5: Weighted mean | S5: Q | T5: Constant prices | U5: A | V5: Annual | W5: 2023 | Y5: 39667.977 | AA5: CRC | AB5: Costa Rican colon | AC5: 2023 | AE5: A | AF5: Normal value | AG5: 0 | AH5: Units | AI5: 2 | AJ5: Two
A6: DATAFLOW | B6: OECD.CTP.TPS:DSD_NECR@DF_NECRS(1.1) | C6: Net effective carbon rates | D6: I | E6: CZE | F6: Czechia | G6: _T | H6: Total | I6: _T | J6: All sources | K6: NETECR | L6: Net effective carbon rate | M6: _Z | N6: Not applicable | O6: XDC_TCO2E | P6: National currency per tonne of CO2-equivalent | Q6: MEANW | R6: Weighted mean | S6: Q | T6: Constant prices | U6: A | V6: Annual | W6: 2023 | Y6: 1634.121 | AA6: CZK | AB6: Czech koruna | AC6: 2023 | AE6: A | AF6: Normal value | AG6: 0 | AH6: Units | AI6: 2 | AJ6: Two
A7: DATAFLOW | B7: OECD.CTP.TPS:DSD_NECR@DF_NECRS(1.1) | C7: Net effective carbon rates | D7: I | E7: DNK | F7: Denmark | G7: _T | H7: Total | I7: _T | J7: All sources | K7: NETECR | L7: Net effective carbon rate | M7: _Z | N7: Not applicable | O7: XDC_TCO2E | P7: National currency per tonne of CO2-equivalent | Q7: MEANW | R7: Weighted mean | S7: Q | T7: Constant prices | U7: A | V7: Annual | W7: 2023 | Y7: 805.61029 | AA7: DKK | AB7: Danish krone | AC7: 2023 | AE7: A | AF7: Normal value | AG7: 0 | AH7: Units | AI7: 2 | AJ7: Two
A8: DATAFLOW | B8: OECD.CTP.TPS:DSD_NECR@DF_NECRS(1.1) | C8: Net effective carbon rates | D8: I | E8: HUN | F8: Hungary | G8: _T | H8: Total | I8: _T | J8: All sources | K8: NETECR | L8: Net effective carbon rate | M8: _Z | N8: Not applicable | O8: XDC_TCO2E | P8: National currency per tonne of CO2-equivalent | Q8: MEANW | R8: Weighted mean | S8: Q | T8: Constant prices | U8: A | V8: Annual | W8: 2023 | Y8: 21136.174 | AA8: HUF | AB8: Forint | AC8: 2023 | AE8: A | AF8: Normal value | AG8: 0 | AH8: Units | AI8: 2 | AJ8: Two
A9: DATAFLOW | B9: OECD.CTP.TPS:DSD_NECR@DF_NECRS(1.1) | C9: Net effective carbon rates | D9: I | E9: ISL | F9: Iceland | G9: _T | H9: Total | I9: _T | J9: All sources | K9: NETECR | L9: Net effective carbon rate | M9: _Z | N9: Not applicable | O9: XDC_TCO2E | P9: National currency per tonne of CO2-equivalent | Q9: MEANW | R9: Weighted mean | S9: Q | T9: Constant prices | U9: A | V9: Annual | W9: 2023 | Y9: 14424.815 | AA9: ISK | AB9: Iceland krona | AC9: 2023 | AE9: A | AF9: Normal value | AG9: 0 | AH9: Units | AI9: 2 | AJ9: Two
A10: DATAFLOW | B10: OECD.CTP.TPS:DSD_NECR@DF_NECRS(1.1) | C10: Net effective carbon rates | D10: I | E10: ISR | F10: Israel | G10: _T | H10: Total | I10: _T | J10: All sources | K10: NETECR | L10: Net effective carbon rate | M10: _Z | N10: Not applicable | O10: XDC_TCO2E | P10: National currency per tonne of CO2-equivalent | Q10: MEANW | R10: Weighted mean | S10: Q | T10: Constant prices | U10: A | V10: Annual | W10: 2023 | Y10: 282.8432 | AA10: ILS | AB10: New Israeli sheqel | AC10: 2023 | AE10: A | AF10: Normal value | AG10: 0 | AH10: Units | AI10: 2 | AJ10: Two
A11: DATAFLOW | B11: OECD.CTP.TPS:DSD_NECR@DF_NECRS(1.1) | C11: Net effective carbon rates | D11: I | E11: JPN | F11: Japan | G11: _T | H11: Total | I11: _T | J11: All sources | K11: NETECR | L11: Net effective carbon rate | M11: _Z | N11: Not applicable | O11: XDC_TCO2E | P11: National currency per tonne of CO2-equivalent | Q11: MEANW | R11: Weighted mean | S11: Q | T11: Constant prices | U11: A | V11: Annual | W11: 2023 | Y11: 873.27972 | AA11: JPY | AB11: Yen | AC11: 2023 | AE11: A | AF11: Normal value | AG11: 0 | AH11: Units | AI11: 2 | AJ11: Two
A12: DATAFLOW | B12: OECD.CTP.TPS:DSD_NECR@DF_NECRS(1.1) | C12: Net effective carbon rates | D12: I | E12: KOR | F12: Korea | G12: _T | H12: Total | I12: _T | J12: All sources | K12: NETECR | L12: Net effective carbon rate | M12: _Z | N12: Not applicable | O12: XDC_TCO2E | P12: National currency per tonne of CO2-equivalent | Q12: MEANW | R12: Weighted mean | S12: Q | T12: Constant prices | U12: A | V12: Annual | W12: 2023 | Y12: 38617.789 | AA12: KRW | AB12: Won | AC12: 2023 | AE12: A | AF12: Normal value | AG12: 0 | AH12: Units | AI12: 2 | AJ12: Two
A13: DATAFLOW | B13: OECD.CTP.TPS:DSD_NECR@DF_NECRS(1.1) | C13: Net effective carbon rates | D13: I | E13: MEX | F13: Mexico | G13: _T | H13: Total | I13: _T | J13: All sources | K13: NETECR | L13: Net effective carbon rate | M13: _Z | N13: Not applicable | O13: XDC_TCO2E | P13: National currency per tonne of CO2-equivalent | Q13: MEANW | R13: Weighted mean | S13: Q | T13: Constant prices | U13: A | V13: Annual | W13: 2023 | Y13: 550.20416 | AA13: MXN | AB13: Mexican peso | AC13: 2023 | AE13: A | AF13: Normal value | AG13: 0 | AH13: Units | AI13: 2 | AJ13: Two
... A134: DATAFLOW | B134: OECD.CTP.TPS:DSD_NECR@DF_NECRS(1.1) | C134: Net effective carbon rates | D134: I | E134: W_X | F134: World unspecified | G134: _T | H134: Total | I134: _T | J134: All sources | K134: NETECR | L134: Net effective carbon rate | M134: _Z | N134: Not applicable | O134: EUR_TCO2E | P134: Euros per tonne of CO2-equivalent | Q134: MEANW | R134: Weighted mean | S134: Q | T134: Constant prices | U134: A | V134: Annual | W134: 2023 | Y134: 14.647834 | AA134: _Z | AB134: Not applicable | AC134: 2023 | AE134: A | AF134: Normal value | AG134: 0 | AH134: Units | AI134: 2 | AJ134: Two

Sheet emission
A1: Entity | B1: Code | C1: Year | D1: Emission | E1: OBS_VALUE | H1: Data source: Global Carbon Budget (2025)
A2: Switzerland | B2: CHE | C2: 2023 | D2: 31977486 | E2: =IFERROR(_xlfn.XLOOKUP(B2,euro!E$2:E$91,euro!Y$2:Y$91),0) -> 168.77026
A3: Luxembourg | B3: LUX | C3: 2023 | D3: 6840733 | E3: =IFERROR(_xlfn.XLOOKUP(B3,euro!E$2:E$91,euro!Y$2:Y$91),0) -> 125.06548
A4: Italy | B4: ITA | C4: 2023 | D4: 312290660 | E4: =IFERROR(_xlfn.XLOOKUP(B4,euro!E$2:E$91,euro!Y$2:Y$91),0) -> 110.8419
A5: Netherlands | B5: NLD | C5: 2023 | D5: 117016380 | E5: =IFERROR(_xlfn.XLOOKUP(B5,euro!E$2:E$91,euro!Y$2:Y$91),0) -> 110.71052
A6: Denmark | B6: DNK | C6: 2023 | D6: 28831184 | E6: =IFERROR(_xlfn.XLOOKUP(B6,euro!E$2:E$91,euro!Y$2:Y$91),0) -> 108.14118
A7: Finland | B7: FIN | C7: 2023 | D7: 31799000 | E7: =IFERROR(_xlfn.XLOOKUP(B7,euro!E$2:E$91,euro!Y$2:Y$91),0) -> 101.84974
A8: Norway | B8: NOR | C8: 2023 | D8: 38869000 | E8: =IFERROR(_xlfn.XLOOKUP(B8,euro!E$2:E$91,euro!Y$2:Y$91),0) -> 101.15076
A9: Iceland | B9: ISL | C9: 2023 | D9: 3508235 | E9: =IFERROR(_xlfn.XLOOKUP(B9,euro!E$2:E$91,euro!Y$2:Y$91),0) -> 96.711327
A10: Germany | B10: DEU | C10: 2023 | D10: 593766000 | E10: =IFERROR(_xlfn.XLOOKUP(B10,euro!E$2:E$91,euro!Y$2:Y$91),0) -> 93.442047
A11: Sweden | B11: SWE | C11: 2023 | D11: 36708596 | E11: =IFERROR(_xlfn.XLOOKUP(B11,euro!E$2:E$91,euro!Y$2:Y$91),0) -> 90.3162
A12: Slovenia | B12: SVN | C12: 2023 | D12: 12012164 | E12: =IFERROR(_xlfn.XLOOKUP(B12,euro!E$2:E$91,euro!Y$2:Y$91),0) -> 88.713989
A13: Portugal | B13: PRT | C13: 2023 | D13: 37622040 | E13: =IFERROR(_xlfn.XLOOKUP(B13,euro!E$2:E$91,euro!Y$2:Y$91),0) -> 87.920753
... A65: Afghanistan | B65: AFG | C65: 2023 | D65: 10516319 | E65: =IFERROR(_xlfn.XLOOKUP(B65,euro!E$2:E$91,euro!Y$2:Y$91),0) -> 0
A66: Africa | C66: 2023 | D66: 1481814400 | E66: =IFERROR(_xlfn.XLOOKUP(B66,euro!E$2:E$91,euro!Y$2:Y$91),0) -> 0
A67: Africa (GCP) | C67: 2023 | D67: 1481803400 | E67: =IFERROR(_xlfn.XLOOKUP(B67,euro!E$2:E$91,euro!Y$2:Y$91),0) -> 0
A68: Albania | B68: ALB | C68: 2023 | D68: 4417333 | E68: =IFERROR(_xlfn.XLOOKUP(B68,euro!E$2:E$91,euro!Y$2:Y$91),0) -> 0
A69: Algeria | B69: DZA | C69: 2023 | D69: 202846660 | E69: =IFERROR(_xlfn.XLOOKUP(B69,euro!E$2:E$91,euro!Y$2:Y$91),0) -> 0
A70: Andorra | B70: AND | C70: 2023 | D70: 418098 | E70: =IFERROR(_xlfn.XLOOKUP(B70,euro!E$2:E$91,euro!Y$2:Y$91),0) -> 0
A71: Angola | B71: AGO | C71: 2023 | D71: 21674816 | E71: =IFERROR(_xlfn.XLOOKUP(B71,euro!E$2:E$91,euro!Y$2:Y$91),0) -> 0
A72: Anguilla | B72: AIA | C72: 2023 | D72: 142607 | E72: =IFERROR(_xlfn.XLOOKUP(B72,euro!E$2:E$91,euro!Y$2:Y$91),0) -> 0
A73: Antarctica | B73: ATA | C73: 2023 | D73: 0 | E73: =IFERROR(_xlfn.XLOOKUP(B73,euro!E$2:E$91,euro!Y$2:Y$91),0) -> 0
A74: Antigua and Barbuda | B74: ATG | C74: 2023 | D74: 640533 | E74: =IFERROR(_xlfn.XLOOKUP(B74,euro!E$2:E$91,euro!Y$2:Y$91),0) -> 0
A75: Armenia | B75: ARM | C75: 2023 | D75: 7430228 | E75: =IFERROR(_xlfn.XLOOKUP(B75,euro!E$2:E$91,euro!Y$2:Y$91),0) -> 0
A76: Aruba | B76: ABW | C76: 2023 | D76: 886584 | E76: =IFERROR(_xlfn.XLOOKUP(B76,euro!E$2:E$91,euro!Y$2:Y$91),0) -> 0
A77: Asia | C77: 2023 | D77: 22997092000 | E77: =IFERROR(_xlfn.XLOOKUP(B77,euro!E$2:E$91,euro!Y$2:Y$91),0) -> 0
A78: Asia (GCP) | C78: 2023 | D78: 20111112000 | E78: =IFERROR(_xlfn.XLOOKUP(B78,euro!E$2:E$91,euro!Y$2:Y$91),0) -> 0
A79: Asia (excl. China and India) | C79: 2023 | D79: 7762327600 | E79: =IFERROR(_xlfn.XLOOKUP(B79,euro!E$2:E$91,euro!Y$2:Y$91),0) -> 0
A80: Azerbaijan | B80: AZE | C80: 2023 | D80: 42748196 | E80: =IFERROR(_xlfn.XLOOKUP(B80,euro!E$2:E$91,euro!Y$2:Y$91),0) -> 0
A81: Bahamas | B81: BHS | C81: 2023 | D81: 2956122 | E81: =IFERROR(_xlfn.XLOOKUP(B81,euro!E$2:E$91,euro!Y$2:Y$91),0) -> 0
A82: Bahrain | B82: BHR | C82: 2023 | D82: 38786692 | E82: =IFERROR(_xlfn.XLOOKUP(B82,euro!E$2:E$91,euro!Y$2:Y$91),0) -> 0
A83: Bangladesh | B83: BGD | C83: 2023 | D83: 104526670 | E83: =IFERROR(_xlfn.XLOOKUP(B83,euro!E$2:E$91,euro!Y$2:Y$91),0) -> 0
A84: Barbados | B84: BRB | C84: 2023 | D84: 1316733 | E84: =IFERROR(_xlfn.XLOOKUP(B84,euro!E$2:E$91,euro!Y$2:Y$91),0) -> 0
A85: Belarus | B85: BLR | C85: 2023 | D85: 55736064 | E85: =IFERROR(_xlfn.XLOOKUP(B85,euro!E$2:E$91,euro!Y$2:Y$91),0) -> 0
A86: Belize | B86: BLZ | C86: 2023 | D86: 766451 | E86: =IFERROR(_xlfn.XLOOKUP(B86,euro!E$2:E$91,euro!Y$2:Y$91),0) -> 0
A87: Benin | B87: BEN | C87: 2023 | D87: 5927823 | E87: =IFERROR(_xlfn.XLOOKUP(B87,euro!E$2:E$91,euro!Y$2:Y$91),0) -> 0
A88: Bermuda | B88: BMU | C88: 2023 | D88: 529653 | E88: =IFERROR(_xlfn.XLOOKUP(B88,euro!E$2:E$91,euro!Y$2:Y$91),0) -> 0
A89: Bhutan | B89: BTN | C89: 2023 | D89: 1629648 | E89: =IFERROR(_xlfn.XLOOKUP(B89,euro!E$2:E$91,euro!Y$2:Y$91),0) -> 0
A90: Bolivia | B90: BOL | C90: 2023 | D90: 24620520 | E90: =IFERROR(_xlfn.XLOOKUP(B90,euro!E$2:E$91,euro!Y$2:Y$91),0) -> 0
A91: Bonaire Sint Eustatius and Saba | B91: BES | C91: 2023 | D91: 146264 | E91: =IFERROR(_xlfn.XLOOKUP(B91,euro!E$2:E$91,euro!Y$2:Y$91),0) -> 0
...

Sheet euro
A1: STRUCTURE | B1: STRUCTURE_ID | C1: STRUCTURE_NAME | D1: ACTION | E1: REF_AREA | F1: Reference area | G1: SECTOR | H1: Economic sector | I1: EMISSIONS_SOURCE | J1: Emissions source | K1: MEASURE | L1: Measure | M1: PRICE_LEVEL | N1: Carbon price level | O1: UNIT_MEASURE | P1: Unit of measure | Q1: STATISTICAL_OPERATION | R1: Statistical operation | S1: PRICE_BASE | T1: Price base | U1: FREQ | V1: Frequency of observation | W1: TIME_PERIOD | X1: Time period | Y1: OBS_VALUE | Z1: Observation value | AA1: CURRENCY | AB1: Currency | AC1: BASE_PER | AD1: Base period | AE1: OBS_STATUS | AF1: Observation status | AG1: UNIT_MULT | AH1: Unit multiplier | AI1: DECIMALS | AJ1: Decimals | AK1: Emission
A2: DATAFLOW | B2: OECD.CTP.TPS:DSD_NECR@DF_NECRS(1.1) | C2: Net effective carbon rates | D2: I | E2: AUT | F2: Austria | G2: _T | H2: Total | I2: _T | J2: All sources | K2: NETECR | L2: Net effective carbon rate | M2: _Z | N2: Not applicable | O2: XDC_TCO2E | P2: National currency per tonne of CO2-equivalent | Q2: MEANW | R2: Weighted mean | S2: Q | T2: Constant prices | U2: A | V2: Annual | W2: 2023 | Y2: 85.875618 | AA2: EUR | AB2: Euro | AC2: 2023 | AE2: A | AF2: Normal value | AG2: 0 | AH2: Units | AI2: 2 | AJ2: Two | AK2: =_xlfn.XLOOKUP(F2,emission!A$2:A$248,emission!D$2:D$248) -> 56908956
A3: DATAFLOW | B3: OECD.CTP.TPS:DSD_NECR@DF_NECRS(1.1) | C3: Net effective carbon rates | D3: I | E3: BEL | F3: Belgium | G3: _T | H3: Total | I3: _T | J3: All sources | K3: NETECR | L3: Net effective carbon rate | M3: _Z | N3: Not applicable | O3: XDC_TCO2E | P3: National currency per tonne of CO2-equivalent | Q3: MEANW | R3: Weighted mean | S3: Q | T3: Constant prices | U3: A | V3: Annual | W3: 2023 | Y3: 82.957512 | AA3: EUR | AB3: Euro | AC3: 2023 | AE3: A | AF3: Normal value | AG3: 0 | AH3: Units | AI3: 2 | AJ3: Two | AK3: =_xlfn.XLOOKUP(F3,emission!A$2:A$248,emission!D$2:D$248) -> 84703360
A4: DATAFLOW | B4: OECD.CTP.TPS:DSD_NECR@DF_NECRS(1.1) | C4: Net effective carbon rates | D4: I | E4: EST | F4: Estonia | G4: _T | H4: Total | I4: _T | J4: All sources | K4: NETECR | L4: Net effective carbon rate | M4: _Z | N4: Not applicable | O4: XDC_TCO2E | P4: National currency per tonne of CO2-equivalent | Q4: MEANW | R4: Weighted mean | S4: Q | T4: Constant prices | U4: A | V4: Annual | W4: 2023 | Y4: 80.378998 | AA4: EUR | AB4: Euro | AC4: 2023 | AE4: A | AF4: Normal value | AG4: 0 | AH4: Units | AI4: 2 | AJ4: Two | AK4: =_xlfn.XLOOKUP(F4,emission!A$2:A$248,emission!D$2:D$248) -> 8744257
A5: DATAFLOW | B5: OECD.CTP.TPS:DSD_NECR@DF_NECRS(1.1) | C5: Net effective carbon rates | D5: I | E5: FIN | F5: Finland | G5: _T | H5: Total | I5: _T | J5: All sources | K5: NETECR | L5: Net effective carbon rate | M5: _Z | N5: Not applicable | O5: XDC_TCO2E | P5: National currency per tonne of CO2-equivalent | Q5: MEANW | R5: Weighted mean | S5: Q | T5: Constant prices | U5: A | V5: Annual | W5: 2023 | Y5: 101.84974 | AA5: EUR | AB5: Euro | AC5: 2023 | AE5: A | AF5: Normal value | AG5: 0 | AH5: Units | AI5: 2 | AJ5: Two | AK5: =_xlfn.XLOOKUP(F5,emission!A$2:A$248,emission!D$2:D$248) -> 31799000
A6: DATAFLOW | B6: OECD.CTP.TPS:DSD_NECR@DF_NECRS(1.1) | C6: Net effective carbon rates | D6: I | E6: FRA | F6: France | G6: _T | H6: Total | I6: _T | J6: All sources | K6: NETECR | L6: Net effective carbon rate | M6: _Z | N6: Not applicable | O6: XDC_TCO2E | P6: National currency per tonne of CO2-equivalent | Q6: MEANW | R6: Weighted mean | S6: Q | T6: Constant prices | U6: A | V6: Annual | W6: 2023 | Y6: 47.142189 | AA6: EUR | AB6: Euro | AC6: 2023 | AE6: A | AF6: Normal value | AG6: 0 | AH6: Units | AI6: 2 | AJ6: Two | AK6: =_xlfn.XLOOKUP(F6,emission!A$2:A$248,emission!D$2:D$248) -> 270262660
A7: DATAFLOW | B7: OECD.CTP.TPS:DSD_NECR@DF_NECRS(1.1) | C7: Net effective carbon rates | D7: I | E7: DEU | F7: Germany | G7: _T | H7: Total | I7: _T | J7: All sources | K7: NETECR | L7: Net effective carbon rate | M7: _Z | N7: Not applicable | O7: XDC_TCO2E | P7: National currency per tonne of CO2-equivalent | Q7: MEANW | R7: Weighted mean | S7: Q | T7: Constant prices | U7: A | V7: Annual | W7: 2023 | Y7: 93.442047 | AA7: EUR | AB7: Euro | AC7: 2023 | AE7: A | AF7: Normal value | AG7: 0 | AH7: Units | AI7: 2 | AJ7: Two | AK7: =_xlfn.XLOOKUP(F7,emission!A$2:A$248,emission!D$2:D$248) -> 593766000
A8: DATAFLOW | B8: OECD.CTP.TPS:DSD_NECR@DF_NECRS(1.1) | C8: Net effective carbon rates | D8: I | E8: GRC | F8: Greece | G8: _T | H8: Total | I8: _T | J8: All sources | K8: NETECR | L8: Net effective carbon rate | M8: _Z | N8: Not applicable | O8: XDC_TCO2E | P8: National currency per tonne of CO2-equivalent | Q8: MEANW | R8: Weighted mean | S8: Q | T8: Constant prices | U8: A | V8: Annual | W8: 2023 | Y8: 76.5933 | AA8: EUR | AB8: Euro | AC8: 2023 | AE8: A | AF8: Normal value | AG8: 0 | AH8: Units | AI8: 2 | AJ8: Two | AK8: =_xlfn.XLOOKUP(F8,emission!A$2:A$248,emission!D$2:D$248) -> 51988224
A9: DATAFLOW | B9: OECD.CTP.TPS:DSD_NECR@DF_NECRS(1.1) | C9: Net effective carbon rates | D9: I | E9: IRL | F9: Ireland | G9: _T | H9: Total | I9: _T | J9: All sources | K9: NETECR | L9: Net effective carbon rate | M9: _Z | N9: Not applicable | O9: XDC_TCO2E | P9: National currency per tonne of CO2-equivalent | Q9: MEANW | R9: Weighted mean | S9: Q | T9: Constant prices | U9: A | V9: Annual | W9: 2023 | Y9: 59.683121 | AA9: EUR | AB9: Euro | AC9: 2023 | AE9: A | AF9: Normal value | AG9: 0 | AH9: Units | AI9: 2 | AJ9: Two | AK9: =_xlfn.XLOOKUP(F9,emission!A$2:A$248,emission!D$2:D$248) -> 33567940
A10: DATAFLOW | B10: OECD.CTP.TPS:DSD_NECR@DF_NECRS(1.1) | C10: Net effective carbon rates | D10: I | E10: ITA | F10: Italy | G10: _T | H10: Total | I10: _T | J10: All sources | K10: NETECR | L10: Net effective carbon rate | M10: _Z | N10: Not applicable | O10: XDC_TCO2E | P10: National currency per tonne of CO2-equivalent | Q10: MEANW | R10: Weighted mean | S10: Q | T10: Constant prices | U10: A | V10: Annual | W10: 2023 | Y10: 110.8419 | AA10: EUR | AB10: Euro | AC10: 2023 | AE10: A | AF10: Normal value | AG10: 0 | AH10: Units | AI10: 2 | AJ10: Two | AK10: =_xlfn.XLOOKUP(F10,emission!A$2:A$248,emission!D$2:D$248) -> 312290660
A11: DATAFLOW | B11: OECD.CTP.TPS:DSD_NECR@DF_NECRS(1.1) | C11: Net effective carbon rates | D11: I | E11: LVA | F11: Latvia | G11: _T | H11: Total | I11: _T | J11: All sources | K11: NETECR | L11: Net effective carbon rate | M11: _Z | N11: Not applicable | O11: XDC_TCO2E | P11: National currency per tonne of CO2-equivalent | Q11: MEANW | R11: Weighted mean | S11: Q | T11: Constant prices | U11: A | V11: Annual | W11: 2023 | Y11: 61.617077 | AA11: EUR | AB11: Euro | AC11: 2023 | AE11: A | AF11: Normal value | AG11: 0 | AH11: Units | AI11: 2 | AJ11: Two | AK11: =_xlfn.XLOOKUP(F11,emission!A$2:A$248,emission!D$2:D$248) -> 6589883
A12: DATAFLOW | B12: OECD.CTP.TPS:DSD_NECR@DF_NECRS(1.1) | C12: Net effective carbon rates | D12: I | E12: LTU | F12: Lithuania | G12: _T | H12: Total | I12: _T | J12: All sources | K12: NETECR | L12: Net effective carbon rate | M12: _Z | N12: Not applicable | O12: XDC_TCO2E | P12: National currency per tonne of CO2-equivalent | Q12: MEANW | R12: Weighted mean | S12: Q | T12: Constant prices | U12: A | V12: Annual | W12: 2023 | Y12: 42.414463 | AA12: EUR | AB12: Euro | AC12: 2023 | AE12: A | AF12: Normal value | AG12: 0 | AH12: Units | AI12: 2 | AJ12: Two | AK12: =_xlfn.XLOOKUP(F12,emission!A$2:A$248,emission!D$2:D$248) -> 12507402
A13: DATAFLOW | B13: OECD.CTP.TPS:DSD_NECR@DF_NECRS(1.1) | C13: Net effective carbon rates | D13: I | E13: LUX | F13: Luxembourg | G13: _T | H13: Total | I13: _T | J13: All sources | K13: NETECR | L13: Net effective carbon rate | M13: _Z | N13: Not applicable | O13: XDC_TCO2E | P13: National currency per tonne of CO2-equivalent | Q13: MEANW | R13: Weighted mean | S13: Q | T13: Constant prices | U13: A | V13: Annual | W13: 2023 | Y13: 125.06548 | AA13: EUR | AB13: Euro | AC13: 2023 | AE13: A | AF13: Normal value | AG13: 0 | AH13: Units | AI13: 2 | AJ13: Two | AK13: =_xlfn.XLOOKUP(F13,emission!A$2:A$248,emission!D$2:D$248) -> 6840733
... A91: DATAFLOW | B91: OECD.CTP.TPS:DSD_NECR@DF_NECRS(1.1) | C91: Net effective carbon rates | D91: I | E91: W_X | F91: World unspecified | G91: _T | H91: Total | I91: _T | J91: All sources | K91: NETECR | L91: Net effective carbon rate | M91: _Z | N91: Not applicable | O91: EUR_TCO2E | P91: Euros per tonne of CO2-equivalent | Q91: MEANW | R91: Weighted mean | S91: Q | T91: Constant prices | U91: A | V91: Annual | W91: 2023 | Y91: 14.647834 | AA91: _Z | AB91: Not applicable | AC91: 2023 | AE91: A | AF91: Normal value | AG91: 0 | AH91: Units | AI91: 2 | AJ91: Two | AK91: =_xlfn.XLOOKUP(F91,emission!A$2:A$248,emission!D$2:D$248) -> #N/A
